<?xml version="1.0"?>
<robot xmlns:xacro="http://ros.org/wiki/xacro" name="neptr">
  <xacro:property name="leg_length" value="0.5"/>
  <xacro:property name="link_width" value="0.05"/>
  
  <link name="base_link">
    <visual>
      <geometry>
        <box size="0.2 0.2 0.1"/>
      </geometry>
      <material name="blue">
        <color rgba="0 0 1 1"/>
      </material>
    </visual>
  </link>

  <!-- Hip Joint -->
  <joint name="hip_joint" type="revolute">
    <parent link="base_link"/>
    <child link="thigh"/>
    <origin xyz="0 0 0.05" rpy="0 0 0"/>
    <axis xyz="0 1 0"/>
    <limit effort="10" velocity="2" lower="-1.57" upper="1.57"/>
  </joint>

  <link name="thigh">
    <visual>
      <geometry>
        <!-- Use xacro to evaluate the expression for the size -->
        <box size="0.05 0.05 0.25"/>
      </geometry>
      <material name="red">
        <color rgba="1 0 0 1"/>
      </material>
    </visual>
  </link>
</robot>
